<?xml version="1.0"?>
<robot xmlns:xacro="http://www.ros.org/wiki/xacro" name="AUV">

  <!-- Include Gazebo-specific plugins -->
  <xacro:include filename="$(find robot_description)/model/robot.gazebo"/>


  <!-- Base Link -->
    <link name="base_link">
        <inertial>
            <origin xyz="0.003846863054427738 6.357883287024561e-17 0.032981473893636044" rpy="0.0 0.0 0.0" />
            <mass value="1.1718649526217775" />
            <inertia ixx="0.004180183045386648" iyy="0.012071423538137577" izz="0.01536721134366918" ixy="3.2668458710929556e-18" iyz="-1.2679790039631697e-18" ixz="-9.099523743467096e-06" />
        </inertial>
        <visual name="base_link_visual">
            <origin xyz="0.0 0.0 0.0" rpy="0.0 0.0 0.0" />
            <geometry>
                <mesh filename="file://$(find robot_description)/meshes/base_link.stl" scale="0.001 0.001 0.001" />
            </geometry>
            <material name="yellow_material">
                <color rgba="1.0 1.0 0.0 1.0"/>
            </material>
        </visual>
        <collision name="base_link_collision">
            <origin xyz="0.0 0.0 0.035" rpy="0.0 0.0 0.0" />
            <geometry>
                    <box size="0.42 0.17 0.07" /> 
            </geometry>
        </collision>
    </link>
    <link name="canister_m1">
        <inertial>
            <origin xyz="-3.400828845201431e-09 5.9839134213460845e-09 -0.01920084938084103" rpy="0.0 -0.0 0.0" />
            <mass value="0.06964931457863664" />
            <inertia ixx="7.159072546589538e-05" iyy="7.159073437891864e-05" izz="8.628303148093433e-05" ixy="-4.076516618729818e-12" iyz="-2.9866608690635572e-12" ixz="3.3172350500168535e-12" />
        </inertial>
        <visual name="canister_m1_visual">
            <origin xyz="-8.881784197001253e-17 7.753917579994428e-18 0.015" rpy="3.141592653589793 3.8857805861880495e-15 3.141592653589793" />
            <geometry>
                <mesh filename="file://$(find robot_description)/meshes/canister_m1.stl" scale="0.001 0.001 0.001" />
            </geometry>
            <material name="black_material">
                <color rgba="0.0 0.0 0.0 1.0"/>
            </material>
        </visual>
        <collision name="canister_m1_collision">
            <origin xyz="-8.881784197001253e-17 7.753917579994428e-18 0.015" rpy="3.141592653589793 3.8857805861880495e-15 3.141592653589793" />
            <geometry>
                <mesh filename="file://$(find robot_description)/meshes/canister_m1.stl" scale="0.001 0.001 0.001" />
            </geometry>
            <material name="black_material">
                <color rgba="0.0 0.0 0.0 1.0"/>
            </material>
        </collision>
    </link>
    <link name="canister_m2">
        <inertial>
            <origin xyz="-3.4008288629649996e-09 5.983913484646441e-09 -0.019200849380841056" rpy="0.0 -0.0 0.0" />
            <mass value="0.06964931457863664" />
            <inertia ixx="7.159072546589527e-05" iyy="7.159073437891885e-05" izz="8.628303148093498e-05" ixy="-4.076516618729818e-12" iyz="-2.9866608690635443e-12" ixz="3.3172350500168535e-12" />
        </inertial>
        <visual name="canister_m2_visual">
            <origin xyz="-8.881784197001253e-17 7.105427357601002e-17 0.014999999999999965" rpy="3.141592653589793 3.8857805861880495e-15 3.141592653589793" />
            <geometry>
                <mesh filename="file://$(find robot_description)/meshes/canister_m2.stl" scale="0.001 0.001 0.001" />
            </geometry>
            <material name="black_material">
                <color rgba="0.0 0.0 0.0 1.0"/>
            </material>
        </visual>
        <collision name="canister_m2_collision">
            <origin xyz="-8.881784197001253e-17 7.105427357601002e-17 0.014999999999999965" rpy="3.141592653589793 3.8857805861880495e-15 3.141592653589793" />
            <geometry>
                <mesh filename="file://$(find robot_description)/meshes/canister_m2.stl" scale="0.001 0.001 0.001" />
            </geometry>
        </collision>
    </link>
    <link name="cannister_s1">
        <inertial>
            <origin xyz="0.012362486832562549 1.2336265342582919e-11 0.047159058143124" rpy="0.0 -0.0 0.0" />
            <mass value="0.06648719130862521" />
            <inertia ixx="7.33445712441964e-05" iyy="9.798304135825563e-05" izz="6.359179198478625e-05" ixy="2.52229335508114e-14" iyz="2.0977956784878904e-14" ixz="1.5222639558599125e-06" />
        </inertial>
        <visual name="cannister_s1_visual">
            <origin xyz="-0.018937499999999875 8.881784197001253e-18 0.07000000000000013" rpy="1.2246467991473527e-16 1.5707963267948946 0" />
            <geometry>
                <mesh filename="file://$(find robot_description)/meshes/cannister_s1.stl" scale="0.001 0.001 0.001" />
            </geometry>
            <material name="black_material">
                <color rgba="0.0 0.0 0.0 1.0"/>
            </material>
        </visual>
        <collision name="cannister_s1_collision">
            <origin xyz="-0.018937499999999875 8.881784197001253e-18 0.07000000000000013" rpy="1.2246467991473527e-16 1.5707963267948946 0" />
            <geometry>
                <mesh filename="file://$(find robot_description)/meshes/cannister_s1.stl" scale="0.001 0.001 0.001" />
            </geometry>
        </collision>
    </link>
    <link name="cannister_s2">
        <inertial>
            <origin xyz="0.012362486832562357 1.2336260901690821e-11 0.047159058143124" rpy="0.0 -0.0 0.0" />
            <mass value="0.06648719130862521" />
            <inertia ixx="7.334457124419619e-05" iyy="9.798304135825563e-05" izz="6.359179198478616e-05" ixy="2.52229335508114e-14" iyz="2.0977848364661655e-14" ixz="1.5222639558598312e-06" />
        </inertial>
        <visual name="cannister_s2_visual">
            <origin xyz="-0.01893750000000016 8.881784197001253e-18 0.06999999999999998" rpy="1.2246467991473527e-16 1.5707963267948946 0" />
            <geometry>
                <mesh filename="file://$(find robot_description)/meshes/cannister_s2.stl" scale="0.001 0.001 0.001" />
            </geometry>
            <material name="black_material">
                <color rgba="0.0 0.0 0.0 1.0"/>
            </material>
        </visual>
        <collision name="cannister_s2_collision">
            <origin xyz="-0.01893750000000016 8.881784197001253e-18 0.06999999999999998" rpy="1.2246467991473527e-16 1.5707963267948946 0" />
            <geometry>
                <mesh filename="file://$(find robot_description)/meshes/cannister_s2.stl" scale="0.001 0.001 0.001" />
            </geometry>
        </collision>
    </link>
    <link name="propeller_m1">
        <inertial>
            <origin xyz="-7.258911268337443e-07 6.479110558665209e-07 -0.0071370406085116125" rpy="0.0 -0.0 0.0" />
            <mass value="0.007313123520405363" />
            <inertia ixx="1.563633227842152e-06" iyy="1.5638676882401178e-06" izz="2.7125943434237303e-06" ixy="-9.069929488221265e-11" iyz="2.0918329126586585e-11" ixz="-2.4984636129363462e-11" />
        </inertial>
        <visual name="propeller_m1_visual">
            <origin xyz="8.881784197001253e-17 7.753917579994408e-18 0.005000000000000036" rpy="3.141592653589793 -7.771561172376099e-15 -4.930380657631324e-32" />
            <geometry>
                <mesh filename="file://$(find robot_description)/meshes/propeller_m1.stl" scale="0.001 0.001 0.001" />
            </geometry>
        </visual>
        <collision name="propeller_m1_collision">
            <origin xyz="8.881784197001253e-17 7.753917579994408e-18 0.005000000000000036" rpy="3.141592653589793 -7.771561172376099e-15 -4.930380657631324e-32" />
            <geometry>
                <mesh filename="file://$(find robot_description)/meshes/propeller_m1.stl" scale="0.001 0.001 0.001" />
            </geometry>
        </collision>
    </link>
    <link name="propeller_m2">
        <inertial>
            <origin xyz="-7.258911268337443e-07 6.479110559298214e-07 -0.007137040608511648" rpy="0.0 -0.0 0.0" />
            <mass value="0.007313123520405363" />
            <inertia ixx="1.5636332278421518e-06" iyy="1.56386768824005e-06" izz="2.7125943434236626e-06" ixy="-9.069929488221276e-11" iyz="2.091832912658659e-11" ixz="-2.498463613190456e-11" />
        </inertial>
        <visual name="propeller_m2_visual">
            <origin xyz="8.881784197001253e-17 7.105427357601e-17 0.005" rpy="3.141592653589793 -7.771561172376099e-15 -4.930380657631324e-32" />
            <geometry>
                <mesh filename="file://$(find robot_description)/meshes/propeller_m2.stl" scale="0.001 0.001 0.001" />
            </geometry>
        </visual>
        <collision name="propeller_m2_collision">
            <origin xyz="8.881784197001253e-17 7.105427357601e-17 0.005" rpy="3.141592653589793 -7.771561172376099e-15 -4.930380657631324e-32" />
            <geometry>
                <mesh filename="file://$(find robot_description)/meshes/propeller_m2.stl" scale="0.001 0.001 0.001" />
            </geometry>
        </collision>
    </link>
    <link name="propeller_s1">
        <inertial>
            <origin xyz="0.0071370406085116845 -6.479110560242418e-07 7.258911269936163e-07" rpy="0.0 -0.0 0.0" />
            <mass value="0.007313123520405363" />
            <inertia ixx="2.712594343423771e-06" iyy="1.563867688240084e-06" izz="1.5636332278421762e-06" ixy="2.0918329094181572e-11" iyz="-9.069929488312927e-11" ixz="-2.4984636118352034e-11" />
        </inertial>
        <visual name="propeller_s1_visual">
            <origin xyz="-0.0049999999999999645 -1.4210854715202004e-16 -8.881784197001253e-18" rpy="1.956768080901675e-15 1.5707963267948966 0" />
            <geometry>
                <mesh filename="file://$(find robot_description)/meshes/propeller_s1.stl" scale="0.001 0.001 0.001" />
            </geometry>
        </visual>
        <collision name="propeller_s1_collision">
            <origin xyz="-0.0049999999999999645 -1.4210854715202004e-16 -8.881784197001253e-18" rpy="1.956768080901675e-15 1.5707963267948966 0" />
            <geometry>
                <mesh filename="file://$(find robot_description)/meshes/propeller_s1.stl" scale="0.001 0.001 0.001" />
            </geometry>
        </collision>
    </link>
    <link name="propeller_s2">
        <inertial>
            <origin xyz="0.007137040608511391 -6.479110560242418e-07 7.25891127006939e-07" rpy="0.0 -0.0 0.0" />
            <mass value="0.007313123520405363" />
            <inertia ixx="2.712594343423744e-06" iyy="1.5638676882400772e-06" izz="1.5636332278421762e-06" ixy="2.0918329134839153e-11" iyz="-9.069929488312927e-11" ixz="-2.4984636121740166e-11" />
        </inertial>
        <visual name="propeller_s2_visual">
            <origin xyz="-0.005000000000000258 -1.5987211554602254e-16 8.881784197001253e-18" rpy="1.956768080901673e-15 1.5707963267948966 0" />
            <geometry>
                <mesh filename="file://$(find robot_description)/meshes/propeller_s2.stl" scale="0.001 0.001 0.001" />
            </geometry>
        </visual>
        <collision name="propeller_s2_collision">
            <origin xyz="-0.005000000000000258 -1.5987211554602254e-16 8.881784197001253e-18" rpy="1.956768080901673e-15 1.5707963267948966 0" />
            <geometry>
                <mesh filename="file://$(find robot_description)/meshes/propeller_s2.stl" scale="0.001 0.001 0.001" />
            </geometry>
        </collision>
    </link>
    <link name="stone">
        <inertial>
            <origin xyz="-0.0030000000000001076 -3.552713678800501e-17 0.0408968735" rpy="0.0 -0.0 0.0" />
            <mass value="2.5" />
            <inertia ixx="0.004789817049047298" iyy="0.0047898170490472975" izz="0.004789817049047303" ixy="-4.283720045350492e-18" iyz="4.2837200453504926e-18" ixz="-5.7462715141731735e-18" />
        </inertial>
        <visual name="stone_visual">
            <origin xyz="-0.003000000000000116 -3.552713678800501e-17 0.0" rpy="3.141592653589793 -0.0 0.0" />
            <geometry>
                <mesh filename="file://$(find robot_description)/meshes/stone.stl" scale="0.001 0.001 0.001" />
            </geometry>
            <material name="black_material">
                <color rgba="0.0 0.0 0.0 1.0"/>
            </material>
        </visual>
        <collision name="stone_collision">
            <origin xyz="-0.003000000000000116 -3.552713678800501e-17 0.0" rpy="3.141592653589793 -0.0 0.0" />
            <geometry>
                <mesh filename="file://$(find robot_description)/meshes/stone.stl" scale="0.001 0.001 0.001" />
            </geometry>
        </collision>
    </link>
    <link name ="camera_link">
        <visual name="camera_visual">
            <origin xyz="0.0 0.0 0.0" rpy="0.0 0.0 0.0" />
            <geometry>
                <box size="0.01 0.01 0.01" />
            </geometry>
            <material name="black_material">
                <color rgba="0.0 0.0 0.0 1.0"/>
            </material>
        </visual>
        <collision name="camera_collision">
            <origin xyz="0.0 0.0 0.0" rpy="0.0 0.0 0.0" />
            <geometry>
                <box size="0.01 0.01 0.01" />
            </geometry>
        </collision>
    </link>
    <link name ="camera_link_down">
        <visual name="camera_down_visual">
            <origin xyz="0.0 0.0 0.0" rpy="0.0 0.0 0.0" />
            <geometry>
                <box size="0.01 0.01 0.01" />
            </geometry>
            <material name="black_material">
                <color rgba="0.0 0.0 0.0 1.0"/>
            </material>
        </visual>
        <collision name="camera_down_collision">
            <origin xyz="0.0 0.0 0.0" rpy="0.0 0.0 0.0" />
            <geometry>
                <box size="0.01 0.01 0.01" />
            </geometry>
        </collision>
    </link>
    <joint name="base_link_Rigid-1" type="fixed">
        <origin xyz="0.125 0.0 0.07" rpy="0.0 -0.0 0.0" />
        <parent link="base_link" />
        <child link="canister_m1" />
    </joint>
    <joint name="base_link_Rigid-2" type="fixed">
        <origin xyz="-0.125 0.0 0.07" rpy="0.0 -0.0 0.0" />
        <parent link="base_link" />
        <child link="canister_m2" />
    </joint>
    <joint name="base_link_Rigid-3" type="fixed">
        <origin xyz="0.005 0.085 0.035" rpy="-1.5707963267948966 -0.0 0.0" />
        <parent link="base_link" />
        <child link="cannister_s1" />
    </joint>
    <joint name="base_link_Rigid-4" type="fixed">
        <origin xyz="0.005 -0.085 0.035" rpy="1.5707963267948966 -0.0 0.0" />
        <parent link="base_link" />
        <child link="cannister_s2" />
    </joint>
    <joint name="canister_m2_Revolute-5" type="continuous">
        <origin xyz="0.0 0.0 -0.055" rpy="-8.758115402030107e-47 -0.0 0.0" />
        <parent link="canister_m2" />
        <child link="propeller_m2" />
        <axis xyz="0.0 8.758115402030107e-47 -1.0" />
    </joint>
    <joint name="canister_m1_Revolute-6" type="continuous">
        <origin xyz="0.0 0.0 -0.055" rpy="-8.758115402030107e-47 -0.0 0.0" />
        <parent link="canister_m1" />
        <child link="propeller_m1" />
        <axis xyz="0.0 8.758115402030107e-47 -1.0" />
    </joint>
    <joint name="cannister_s1_Revolute-7" type="continuous">
        <origin xyz="0.051062500000000004 0.0 0.07" rpy="1.5707963267948966 -3.489561605495647e-47 3.944304526105059e-31" />
        <parent link="cannister_s1" />
        <child link="propeller_s1" />
        <axis xyz="1.0 0.0 3.672378311415789e-31" />
    </joint>
    <joint name="cannister_s2_Revolute-8" type="continuous">
        <origin xyz="0.051062500000000004 0.0 0.07" rpy="-1.5707963267948966 -4.667261458395856e-61 3.944304526105059e-31" />
        <parent link="cannister_s2" />
        <child link="propeller_s2" />
        <axis xyz="1.0 0.0 -3.6723783114154653e-31" />
    </joint>
    <joint name="base_link_Rigid-9" type="fixed">
        <origin xyz="0.0 0.0 0.0" rpy="3.141592653589793 -0.0 0.0" />
        <parent link="base_link" />
        <child link="stone" />
    </joint>
    <joint name="base_link_Rigid-10" type="fixed">
        <origin xyz="0.21 0.0 0.0" rpy="0.0 0.0 0.0" />
        <parent link="base_link" />
        <child link="camera_link" />
    </joint>
    <joint name="base_link_Rigid-11" type="fixed">
        <origin xyz="0.21 0.0 0.0" rpy="0.0 1.57 0.0" />
        <parent link="base_link" />
        <child link="camera_link_down" />
    </joint>

</robot>